Workbook
Name CertCode: General!$F$4
Name CertDate: [1]General!$F$5
Name CertDate: General!$F$5
Name CertHR: [2]General!$I$13
Name CertHR: [1]General!$I$13
Name CertHR: General!$I$13
Name CertHRIncerti: [2]General!$I$14
Name CertHRIncerti: [1]General!$I$14
Name CertHRIncerti: General!$I$14
Name CertNum: [1]General!$F$3
Name CertNum: General!$F$3
Name CertPres: General!$I$18
Name CertPresIncert: General!$I$19
Name CertTempC: [2]General!$I$8
Name CertTempC: [1]General!$I$8
Name CertTempC: General!$I$8
Name CertTempFin: General!$I$7
Name CertTempIncerti: [2]General!$I$9
Name CertTempIncerti: [1]General!$I$9
Name CertTempIncerti: General!$I$9
Name CertTempIni: General!$I$6
Name ClientAdr: General!$L$4
Name ClientName: General!$L$3
Name ClientPlace: General!$L$5
Name coef_unidad: [2]Calibración!$E$7
Name coef_unidad: [1]Calibración!$E$7
Name coef_unidad: Calibración!$E$7
Name decim: [2]Calibración!$F$9
Name decim: [1]Calibración!$F$9
Name decim: Calibración!$F$9
Name deltaMconv: '[3]BD Patron'!$AM$17:$AT$28
Name deltaT: '[3]BD Patron'!$AM$16:$AT$16
Name DivEscalaPatr: [2]Calibración!$J$6
Name DivEscalaPatr: [1]Calibración!$J$6
Name DivEscalaPatr: Calibración!$J$6
Name Histeresis: [2]Calibración!$P$4
Name Histeresis: [1]Calibración!$P$4
Name Histeresis: Calibración!$P$4
Name Incert_Pozo: [2]Calibración!$Q$10
Name Incert_Pozo: [1]Calibración!$Q$10
Name Incert_Pozo: Calibración!$Q$10
Name MnomDeltaT: '[3]BD Patron'!$AL$17:$AL$28
Name NumPuntosCalib: [2]Calibración!$P$40
Name NumPuntosCalib: [1]Calibración!$P$40
Name NumPuntosCalib: Calibración!$P$40
Name RangoMedida: [2]General!$F$11
Name RangoMedida: [1]General!$F$11
Name RangoMedida: General!$F$11
Name Rcuadrado: Calibración!$O$41
Name ResolTerm: [2]Calibración!$F$5
Name ResolTerm: [1]Calibración!$F$5
Name ResolTerm: Calibración!$F$5
Name RngLinealidad: [3]Calibración!$C$34:$C$44
Name tblComp_U: [2]!tblCompU[#Data]
Name tblComp_U: [1]!tblCompU[#Data]
Name tblComp_U: 'kU(E)'!$B$9:$P$16
Name TermometroCode: [1]General!$F$6
Name TermometroCode: General!$F$6
Name TermometroIncertid: General!$F$13
Name TermometroMarca: General!$F$8

Sheet NI-R01-MCIT-T-01
A5: 1. INFORMACIÓN DEL CLIENTE
A6: Empresa | B6: Agricola Nicavista | G6: Fecha | H6: 44964
A7: Lugar de calibración | C7: Laboratorio | G7: NI-CS- | H7: NI-CS-0063-23
A9: 2. INFORMACIÓN EQUIPO
A10: Descripción dispositivo
A11: Fabricante/Marca | E11: Unidad
A12: No de serie | E12: Modelo
A13: Rango de medida | E13: Código
A14: Resolución | E14: Analógico | G14: Digital
A16: 3. CONDICIONES AMBIENTALES
A17: Condiciones Ambientales | B17: T. A. (ºC): | C17: HR (%): | D17: Higrotermómetro código: | F17: PA (hPa) | G17: Barómetro código | I17: t estabilización [minutos]
A18: Iniciales
A19: Finales
A21: 4. RESULTADOS DE LA CALIBRACIÓN
B22: Linealidad
B23: Indicación del patrón | C23: Indicación del termómetro | D23: Indicación del patrón | E23: Indicación del termómetro | F23: Indicación del patrón | G23: Indicación del termómetro
A35: 5. DESCRIPCIÓN DEL METODO
A36: NI-MCIT-T-01 Instrucción para calibración de termómetros
A38: 6. DESCRIPCIÓN DE LOS PATRONES UTILIZADOS
A39: NI-MCPT- | C39: NI-MCPT- | E39: NI-MCPT-
A40: NI-MCPT- | C40: NI-MCPT- | E40: NI-MCPT-
A42: 7. OBSERVACIONES
A46: 8. REALIZADO POR | E46: REVISADO Y APROBADO
A47: Firma: | E47: Firma:
A49: 9. NÚMERO DE CERTIFICADO | D49: EMITIÓ | G49: FECHA
A50: NI-MC-T-1325-2023 | D50: Firma:

Sheet General
B2: Hoja de cálculo | C2: Detalles | E2: Certificado Balanza | F2: Detalles | H2: Condiciones ambientales | I2: Detalles | K2: Cliente | L2: Detalles
B3: Código | C3: NI-R02-MCIT-T-01 | E3: Identificación del certificado | F3: ='NI-R01-MCIT-T-01'!A50 -> NI-MC-T-1325-2023 | H3: Lugar de calibración | I3: in situ | K3: Solicitante | L3: ='NI-R01-MCIT-T-01'!B6 -> Agricola Nicavista
B4: Versión | C4: 3 | E4: Código de servicio | F4: ='NI-R01-MCIT-T-01'!H7 -> NI-CS-0063-23 | H4: Higrotermometro código | I4: ='NI-R01-MCIT-T-01'!D18 -> 0 | K4: Dirección del solicitante | L4: =IFERROR(VLOOKUP(L3,tblClientes[[Nombre]:[Direccion]],2,FALSE),"") -> Ciudad Rama, Atlántico Sur, Nicaragua
B5: Fecha de revisión | C5: 43170 | E5: Fecha de calibración | F5: ='NI-R01-MCIT-T-01'!H6 -> 44964 | H5: Higrotermometro marca | I5: =VLOOKUP(I4,'BD Patron'!C6:L10,2,FALSE) -> #N/A | K5: Lugar de calibración | L5: ='NI-R01-MCIT-T-01'!C7 -> Laboratorio
B6: Fecha de validación | C6: 43139 | E6: Código de identificación | F6: ='NI-R01-MCIT-T-01'!F13 -> 0 | H6: Temperatura ambiental inicial, °C | I6: ='NI-R01-MCIT-T-01'!B18 -> 0
B7: Fecha de aprobación | E7: Objeto de calibración | F7: ='NI-R01-MCIT-T-01'!C10 -> 0 | H7: Temperatura ambiental final, °C | I7: ='NI-R01-MCIT-T-01'!B19 -> 0
B8: Aprobada por | E8: Fabricante / Marca | F8: ='NI-R01-MCIT-T-01'!C11 -> 0 | H8: Promedio temperaturas, °C | I8: =IFERROR(AVERAGE(I6:I7),"") -> 0
B9: Director técnico | C9: Ing. Fredman A. Méndez M. | E9: Modelo | F9: ='NI-R01-MCIT-T-01'!F12 -> 0 | H9: Exactitud med. temp. ambiental ± 0C | I9: =VLOOKUP(I4,'BD Patron'!C6:L10,8,FALSE) -> #N/A
B10: Director calidad | C10: Ing. Fredman A. Méndez M. | E10: Serie | F10: ='NI-R01-MCIT-T-01'!C12 -> 0 | H10: Resolución temperatura higrotm. 0C | I10: =VLOOKUP(I4,'BD Patron'!C6:L10,4,FALSE) -> #N/A
E11: Rango de medida | F11: ='NI-R01-MCIT-T-01'!C13 -> 0 | H11: Humedad relativa inicial, % | I11: ='NI-R01-MCIT-T-01'!C18 -> 0
E12: Resolución | F12: ='NI-R01-MCIT-T-01'!C14 -> 0 | H12: Humedad relativa final, % | I12: ='NI-R01-MCIT-T-01'!C19 -> 0
C13: Fórmulas de búsqueda | E13: Incertidumbre fabricante ± | H13: Promedio humedad relativa, % | I13: =IFERROR(AVERAGE(I11:I12),"") -> 0
H14: Exactitud medición HR ± % | I14: =VLOOKUP(I4,'BD Patron'!C6:L10,9,FALSE) -> #N/A
C15: Celdas fuente listas despl. | H15: Resolución higrotermometro HR % | I15: =VLOOKUP(I4,'BD Patron'!C6:L10,5,FALSE) -> #N/A
H16: Presión barométrica inicial, hPa | I16: ='NI-R01-MCIT-T-01'!F18 -> 0
C17: Resultados de cálculos | H17: Presión barométrica final, hPa | I17: ='NI-R01-MCIT-T-01'!F19 -> 0
H18: Promedio presión barométrica, hPa | I18: =IFERROR(AVERAGE(I16:I17),"") -> 0
C19: Celda condicional | H19: Exactitud medición PB ± | I19: 10
W98: Datalogger
W99: Termómetro Analógico
W100: Termómetro Digital
W101: Termómetro Bimetálico
W102: Termómetro Infrarrojo
W103: Termómetro Líquido en Vidrio
W104: Termo Balanza
W105: Termoregistrador
W106: Transmisores de Temperatura
W107: Sensor de RTD
W108: Sensor Termopar
W109: Sensor Termocupla
... W127: No aplica

Sheet kU(E)
B2: Presupuesto de incertidumbre expandida | G2: Nota de mantenimiento de la hoja: si mueve la tabla de componentes de incertidumbre, tiene que
B3: Parámetro | C3: Símbolo | D3: Unidad | E3: Valor | G3: componer las fórmulas, ya que hacen referencia en la octava línea de esta hoja de Excel,
B4: Dif. temps. entre ambiente y patrón | C4: DT | D4: °C | E4: 0 | G4: que es la línea de los encabezados de la tabla.
B5: Tiempo ambientación | C5: tamb. | D5: min | E5: 30
B7: Componentes incertidumbre combinada todos los puntos calibración | G7: =IFERROR(CONCATENATE(FIXED(Calibración!C32,decim),unidad),"") -> 0.0°C | H7: =IFERROR(CONCATENATE(FIXED(Calibración!C33,decim),unidad),"") -> 0.0°C | I7: =IFERROR(CONCATENATE(FIXED(Calibración!C34,decim),unidad),"") -> 0.0°C | J7: =IFERROR(CONCATENATE(FIXED(Calibración!C35,decim),unidad),"") -> 0.0°C | K7: =IFERROR(CONCATENATE(FIXED(Calibración!C36,decim),unidad),"") -> 0.0°C | L7: =IFERROR(CONCATENATE(FIXED(Calibración!C37,decim),unidad),"") -> 0.0°C | M7: =IFERROR(CONCATENATE(FIXED(Calibración!C38,decim),unidad),"") -> 0.0°C | N7: =IFERROR(CONCATENATE(FIXED(Calibración!C39,decim),unidad),"") -> 0.0°C | O7: =IFERROR(CONCATENATE(FIXED(Calibración!C40,decim),unidad),"") -> 0.0°C | P7: =IFERROR(CONCATENATE(FIXED(Calibración!C41,decim),unidad),"") -> 0.0°C
B8: Fuente de incertidumbre | C8: Símbolo | D8: Distrib. | E8: Divisor | F8: Coef. ci | G8: 1 | H8: 2 | I8: 3 | J8: 4 | K8: 5 | L8: 6 | M8: 7 | N8: 8 | O8: 9 | P8: 10
B9: Resolución del patrón | C9: u(dPd) | D9: Rectang. | E9: =SQRT(12) -> 3.4641016 | F9: 1 | G9: =IF(G10=0,0,DivEscalaPatr*'kU(E)'!$F9/'kU(E)'!$E9) -> 0.00028867513 | H9: =IF(H10=0,0,DivEscalaPatr*'kU(E)'!$F9/'kU(E)'!$E9) -> 0.00028867513 | I9: =IF(I10=0,0,DivEscalaPatr*'kU(E)'!$F9/'kU(E)'!$E9) -> 0.00028867513 | J9: =IF(J10=0,0,DivEscalaPatr*'kU(E)'!$F9/'kU(E)'!$E9) -> 0.00028867513 | K9: =IF(K10=0,0,DivEscalaPatr*'kU(E)'!$F9/'kU(E)'!$E9) -> 0.00028867513 | L9: =IF(L10=0,0,DivEscalaPatr*'kU(E)'!$F9/'kU(E)'!$E9) -> 0.00028867513 | M9: =IF(M10=0,0,DivEscalaPatr*'kU(E)'!$F9/'kU(E)'!$E9) -> 0.00028867513 | N9: =IF(N10=0,0,DivEscalaPatr*'kU(E)'!$F9/'kU(E)'!$E9) -> 0.00028867513 | ... P9: =IF(P10=0,0,DivEscalaPatr*'kU(E)'!$F9/'kU(E)'!$E9) -> 0.00028867513
B10: Incertidumbre calibración del patron | C10: u(dPref.) | D10: Normal | E10: 2 | F10: 1 | G10: =IFERROR(INDEX(tblResultCalib[Incertid. patrón],MATCH(_xlfn.NUMBERVALUE(INDIRECT(ADDRESS(8,COLUMN()))),tblResultCalib['#],0))*'kU(E)'!$F10/'kU(E)'!$E10,0) -> 0.01 | H10: =IFERROR(INDEX(tblResultCalib[Incertid. patrón],MATCH(_xlfn.NUMBERVALUE(INDIRECT(ADDRESS(8,COLUMN()))),tblResultCalib['#],0))*'kU(E)'!$F10/'kU(E)'!$E10,0) -> 0.01 | I10: =IFERROR(INDEX(tblResultCalib[Incertid. patrón],MATCH(_xlfn.NUMBERVALUE(INDIRECT(ADDRESS(8,COLUMN()))),tblResultCalib['#],0))*'kU(E)'!$F10/'kU(E)'!$E10,0) -> 0.01 | J10: =IFERROR(INDEX(tblResultCalib[Incertid. patrón],MATCH(_xlfn.NUMBERVALUE(INDIRECT(ADDRESS(8,COLUMN()))),tblResultCalib['#],0))*'kU(E)'!$F10/'kU(E)'!$E10,0) -> 0.01 | K10: =IFERROR(INDEX(tblResultCalib[Incertid. patrón],MATCH(_xlfn.NUMBERVALUE(INDIRECT(ADDRESS(8,COLUMN()))),tblResultCalib['#],0))*'kU(E)'!$F10/'kU(E)'!$E10,0) -> 0.01 | L10: =IFERROR(INDEX(tblResultCalib[Incertid. patrón],MATCH(_xlfn.NUMBERVALUE(INDIRECT(ADDRESS(8,COLUMN()))),tblResultCalib['#],0))*'kU(E)'!$F10/'kU(E)'!$E10,0) -> 0.01 | M10: =IFERROR(INDEX(tblResultCalib[Incertid. patrón],MATCH(_xlfn.NUMBERVALUE(INDIRECT(ADDRESS(8,COLUMN()))),tblResultCalib['#],0))*'kU(E)'!$F10/'kU(E)'!$E10,0) -> 0.01 | N10: =IFERROR(INDEX(tblResultCalib[Incertid. patrón],MATCH(_xlfn.NUMBERVALUE(INDIRECT(ADDRESS(8,COLUMN()))),tblResultCalib['#],0))*'kU(E)'!$F10/'kU(E)'!$E10,0) -> 0.01 | ... P10: =IFERROR(INDEX(tblResultCalib[Incertid. patrón],MATCH(_xlfn.NUMBERVALUE(INDIRECT(ADDRESS(8,COLUMN()))),tblResultCalib['#],0))*'kU(E)'!$F10/'kU(E)'!$E10,0) -> 0.01
B11: Interpolación corrección del patrón | C11: u(dPint.) | D11: Triangular | E11: =SQRT(6) -> 2.4494897 | F11: 1 | G11: =IFERROR(INDEX(tblResultCalib[Corrección patrón],MATCH(_xlfn.NUMBERVALUE(INDIRECT(ADDRESS(8,COLUMN()))),tblResultCalib['#],0))*'kU(E)'!$F11/'kU(E)'!$E11,0) -> -0.00082294621 | H11: =IFERROR(INDEX(tblResultCalib[Corrección patrón],MATCH(_xlfn.NUMBERVALUE(INDIRECT(ADDRESS(8,COLUMN()))),tblResultCalib['#],0))*'kU(E)'!$F11/'kU(E)'!$E11,0) -> -0.00082294621 | I11: =IFERROR(INDEX(tblResultCalib[Corrección patrón],MATCH(_xlfn.NUMBERVALUE(INDIRECT(ADDRESS(8,COLUMN()))),tblResultCalib['#],0))*'kU(E)'!$F11/'kU(E)'!$E11,0) -> -0.00082294621 | J11: =IFERROR(INDEX(tblResultCalib[Corrección patrón],MATCH(_xlfn.NUMBERVALUE(INDIRECT(ADDRESS(8,COLUMN()))),tblResultCalib['#],0))*'kU(E)'!$F11/'kU(E)'!$E11,0) -> -0.00082294621 | K11: =IFERROR(INDEX(tblResultCalib[Corrección patrón],MATCH(_xlfn.NUMBERVALUE(INDIRECT(ADDRESS(8,COLUMN()))),tblResultCalib['#],0))*'kU(E)'!$F11/'kU(E)'!$E11,0) -> -0.00082294621 | L11: =IFERROR(INDEX(tblResultCalib[Corrección patrón],MATCH(_xlfn.NUMBERVALUE(INDIRECT(ADDRESS(8,COLUMN()))),tblResultCalib['#],0))*'kU(E)'!$F11/'kU(E)'!$E11,0) -> -0.00082294621 | M11: =IFERROR(INDEX(tblResultCalib[Corrección patrón],MATCH(_xlfn.NUMBERVALUE(INDIRECT(ADDRESS(8,COLUMN()))),tblResultCalib['#],0))*'kU(E)'!$F11/'kU(E)'!$E11,0) -> -0.00082294621 | N11: =IFERROR(INDEX(tblResultCalib[Corrección patrón],MATCH(_xlfn.NUMBERVALUE(INDIRECT(ADDRESS(8,COLUMN()))),tblResultCalib['#],0))*'kU(E)'!$F11/'kU(E)'!$E11,0) -> -0.00082294621 | ... P11: =IFERROR(INDEX(tblResultCalib[Corrección patrón],MATCH(_xlfn.NUMBERVALUE(INDIRECT(ADDRESS(8,COLUMN()))),tblResultCalib['#],0))*'kU(E)'!$F11/'kU(E)'!$E11,0) -> -0.00082294621
A12: Sí | B12: Deriva patrón | C12: u(dPder.) | D12: Rectang. | E12: =SQRT(3) -> 1.7320508 | F12: 1 | G12: =IF($A$12="No",0,IFERROR(INDEX(tblResultCalib[Deriva patrón],MATCH(_xlfn.NUMBERVALUE(INDIRECT(ADDRESS(8,COLUMN()))),tblResultCalib['#],0))*'kU(E)'!$F12/'kU(E)'!$E12,0)) -> 0.00058522762 | H12: =IF($A$12="No",0,IFERROR(INDEX(tblResultCalib[Deriva patrón],MATCH(_xlfn.NUMBERVALUE(INDIRECT(ADDRESS(8,COLUMN()))),tblResultCalib['#],0))*'kU(E)'!$F12/'kU(E)'!$E12,0)) -> 0.00058522762 | I12: =IF($A$12="No",0,IFERROR(INDEX(tblResultCalib[Deriva patrón],MATCH(_xlfn.NUMBERVALUE(INDIRECT(ADDRESS(8,COLUMN()))),tblResultCalib['#],0))*'kU(E)'!$F12/'kU(E)'!$E12,0)) -> 0.00058522762 | J12: =IF($A$12="No",0,IFERROR(INDEX(tblResultCalib[Deriva patrón],MATCH(_xlfn.NUMBERVALUE(INDIRECT(ADDRESS(8,COLUMN()))),tblResultCalib['#],0))*'kU(E)'!$F12/'kU(E)'!$E12,0)) -> 0.00058522762 | K12: =IF($A$12="No",0,IFERROR(INDEX(tblResultCalib[Deriva patrón],MATCH(_xlfn.NUMBERVALUE(INDIRECT(ADDRESS(8,COLUMN()))),tblResultCalib['#],0))*'kU(E)'!$F12/'kU(E)'!$E12,0)) -> 0.00058522762 | L12: =IF($A$12="No",0,IFERROR(INDEX(tblResultCalib[Deriva patrón],MATCH(_xlfn.NUMBERVALUE(INDIRECT(ADDRESS(8,COLUMN()))),tblResultCalib['#],0))*'kU(E)'!$F12/'kU(E)'!$E12,0)) -> 0.00058522762 | M12: =IF($A$12="No",0,IFERROR(INDEX(tblResultCalib[Deriva patrón],MATCH(_xlfn.NUMBERVALUE(INDIRECT(ADDRESS(8,COLUMN()))),tblResultCalib['#],0))*'kU(E)'!$F12/'kU(E)'!$E12,0)) -> 0.00058522762 | N12: =IF($A$12="No",0,IFERROR(INDEX(tblResultCalib[Deriva patrón],MATCH(_xlfn.NUMBERVALUE(INDIRECT(ADDRESS(8,COLUMN()))),tblResultCalib['#],0))*'kU(E)'!$F12/'kU(E)'!$E12,0)) -> 0.00058522762 | ... P12: =IF($A$12="No",0,IFERROR(INDEX(tblResultCalib[Deriva patrón],MATCH(_xlfn.NUMBERVALUE(INDIRECT(ADDRESS(8,COLUMN()))),tblResultCalib['#],0))*'kU(E)'!$F12/'kU(E)'!$E12,0)) -> 0.00058522762
B13: Caracerisiticas medio isotermo | C13: u(δMiso) | D13: Rectang. | E13: =SQRT(3) -> 1.7320508 | F13: 1 | G13: =IF(G10=0,0,Incert_Pozo*'kU(E)'!$F13/'kU(E)'!$E13) -> 0.011902381 | H13: =IF(H10=0,0,Incert_Pozo*'kU(E)'!$F13/'kU(E)'!$E13) -> 0.011902381 | I13: =IF(I10=0,0,Incert_Pozo*'kU(E)'!$F13/'kU(E)'!$E13) -> 0.011902381 | J13: =IF(J10=0,0,Incert_Pozo*'kU(E)'!$F13/'kU(E)'!$E13) -> 0.011902381 | K13: =IF(K10=0,0,Incert_Pozo*'kU(E)'!$F13/'kU(E)'!$E13) -> 0.011902381 | L13: =IF(L10=0,0,Incert_Pozo*'kU(E)'!$F13/'kU(E)'!$E13) -> 0.011902381 | M13: =IF(M10=0,0,Incert_Pozo*'kU(E)'!$F13/'kU(E)'!$E13) -> 0.011902381 | N13: =IF(N10=0,0,Incert_Pozo*'kU(E)'!$F13/'kU(E)'!$E13) -> 0.011902381 | ... P13: =IF(P10=0,0,Incert_Pozo*'kU(E)'!$F13/'kU(E)'!$E13) -> 0.011902381
B14: Resolución del instrumento | C14: u(δTd) | D14: Rectang. | E14: =2*SQRT(3) -> 3.4641016 | F14: 1 | G14: =IF(G10=0,0,ResolTerm*'kU(E)'!$F14/'kU(E)'!$E14) -> 0.057735027 | H14: =IF(H10=0,0,ResolTerm*'kU(E)'!$F14/'kU(E)'!$E14) -> 0.057735027 | I14: =IF(I10=0,0,ResolTerm*'kU(E)'!$F14/'kU(E)'!$E14) -> 0.057735027 | J14: =IF(J10=0,0,ResolTerm*'kU(E)'!$F14/'kU(E)'!$E14) -> 0.057735027 | K14: =IF(K10=0,0,ResolTerm*'kU(E)'!$F14/'kU(E)'!$E14) -> 0.057735027 | L14: =IF(L10=0,0,ResolTerm*'kU(E)'!$F14/'kU(E)'!$E14) -> 0.057735027 | M14: =IF(M10=0,0,ResolTerm*'kU(E)'!$F14/'kU(E)'!$E14) -> 0.057735027 | N14: =IF(N10=0,0,ResolTerm*'kU(E)'!$F14/'kU(E)'!$E14) -> 0.057735027 | ... P14: =IF(P10=0,0,ResolTerm*'kU(E)'!$F14/'kU(E)'!$E14) -> 0.057735027
B15: Repetibilidad del instrumento | C15: u(Trep) | D15: Rectang. | E15: =SQRT(3) -> 1.7320508 | F15: 1 | G15: =IFERROR(OFFSET(Calibración!$K$15,G$8-1,0)*'kU(E)'!$F15/'kU(E)'!$E15,0) -> 0 | H15: =IFERROR(Calibración!$K16*'kU(E)'!$F15/'kU(E)'!$E15,0) -> 0 | I15: =IFERROR(Calibración!$K17*'kU(E)'!$F15/'kU(E)'!$E15,0) -> 0 | J15: =IFERROR(Calibración!$K18*'kU(E)'!$F15/'kU(E)'!$E15,0) -> 0 | K15: =IFERROR(Calibración!$K19*'kU(E)'!$F15/'kU(E)'!$E15,0) -> 0 | L15: =IFERROR(Calibración!$K20*'kU(E)'!$F15/'kU(E)'!$E15,0) -> 0 | M15: =IFERROR(Calibración!$K21*'kU(E)'!$F15/'kU(E)'!$E15,0) -> 0 | N15: =IFERROR(Calibración!$K22*'kU(E)'!$F15/'kU(E)'!$E15,0) -> 0 | O15: =IFERROR(Calibración!$K23*'kU(E)'!$F15/'kU(E)'!$E15,0) -> 0 | P15: =IFERROR(Calibración!$K24*'kU(E)'!$F15/'kU(E)'!$E15,0) -> 0
B16: Influencia ambiental | C16: u(dPt) | D16: Rectang. | E16: =SQRT(3) -> 1.7320508 | F16: 1 | G16: =IFERROR(IF(G10=0,0,SQRT(IFERROR(POWER(OFFSET(Calibración!$U$15,G$8-1,0)*'kU(E)'!$F16/'kU(E)'!$E16,2),0)+IFERROR(POWER(OFFSET(Calibración!$V$15,G$8-1,0)*'kU(E)'!$F16/'kU(E)'!$E16,2),0))),0) -> 0 | H16: =IFERROR(IF(H10=0,0,SQRT(IFERROR(POWER(OFFSET(Calibración!$U$15,H$8-1,0)*'kU(E)'!$F16/'kU(E)'!$E16,2),0)+IFERROR(POWER(OFFSET(Calibración!$V$15,H$8-1,0)*'kU(E)'!$F16/'kU(E)'!$E16,2),0))),0) -> 0 | I16: =IFERROR(IF(I10=0,0,SQRT(IFERROR(POWER(OFFSET(Calibración!$U$15,I$8-1,0)*'kU(E)'!$F16/'kU(E)'!$E16,2),0)+IFERROR(POWER(OFFSET(Calibración!$V$15,I$8-1,0)*'kU(E)'!$F16/'kU(E)'!$E16,2),0))),0) -> 0 | J16: =IFERROR(IF(J10=0,0,SQRT(IFERROR(POWER(OFFSET(Calibración!$U$15,J$8-1,0)*'kU(E)'!$F16/'kU(E)'!$E16,2),0)+IFERROR(POWER(OFFSET(Calibración!$V$15,J$8-1,0)*'kU(E)'!$F16/'kU(E)'!$E16,2),0))),0) -> 0 | K16: =IFERROR(IF(K10=0,0,SQRT(IFERROR(POWER(OFFSET(Calibración!$U$15,K$8-1,0)*'kU(E)'!$F16/'kU(E)'!$E16,2),0)+IFERROR(POWER(OFFSET(Calibración!$V$15,K$8-1,0)*'kU(E)'!$F16/'kU(E)'!$E16,2),0))),0) -> 0 | L16: =IFERROR(IF(L10=0,0,SQRT(IFERROR(POWER(OFFSET(Calibración!$U$15,L$8-1,0)*'kU(E)'!$F16/'kU(E)'!$E16,2),0)+IFERROR(POWER(OFFSET(Calibración!$V$15,L$8-1,0)*'kU(E)'!$F16/'kU(E)'!$E16,2),0))),0) -> 0 | M16: =IFERROR(IF(M10=0,0,SQRT(IFERROR(POWER(OFFSET(Calibración!$U$15,M$8-1,0)*'kU(E)'!$F16/'kU(E)'!$E16,2),0)+IFERROR(POWER(OFFSET(Calibración!$V$15,M$8-1,0)*'kU(E)'!$F16/'kU(E)'!$E16,2),0))),0) -> 0 | N16: =IFERROR(IF(N10=0,0,SQRT(IFERROR(POWER(OFFSET(Calibración!$U$15,N$8-1,0)*'kU(E)'!$F16/'kU(E)'!$E16,2),0)+IFERROR(POWER(OFFSET(Calibración!$V$15,N$8-1,0)*'kU(E)'!$F16/'kU(E)'!$E16,2),0))),0) -> 0 | ... P16: =IFERROR(IF(P10=0,0,SQRT(IFERROR(POWER(OFFSET(Calibración!$U$15,P$8-1,0)*'kU(E)'!$F16/'kU(E)'!$E16,2),0)+IFERROR(POWER(OFFSET(Calibración!$V$15,P$8-1,0)*'kU(E)'!$F16/'kU(E)'!$E16,2),0))),0) -> 0
B17: Total | C17: Raíz de la | D17: suma cuadr. | E17: =CONCATENATE("Todo en [",unidad,"]") -> Todo en [°C] | G17: =SQRT(SUMSQ(G9:G16)) -> 0.059800527 | H17: =SQRT(SUMSQ(H9:H16)) -> 0.059800527 | I17: =SQRT(SUMSQ(I9:I16)) -> 0.059800527 | J17: =SQRT(SUMSQ(J9:J16)) -> 0.059800527 | K17: =SQRT(SUMSQ(K9:K16)) -> 0.059800527 | L17: =SQRT(SUMSQ(L9:L16)) -> 0.059800527 | M17: =SQRT(SUMSQ(M9:M16)) -> 0.059800527 | N17: =SQRT(SUMSQ(N9:N16)) -> 0.059800527 | ... P17: =SQRT(SUMSQ(P9:P16)) -> 0.059800527
B21: Componentes incertidumbre combinada todos los puntos calibración | G21: =G7 -> 0.0°C | H21: =H7 -> 0.0°C | I21: =I7 -> 0.0°C | J21: =J7 -> 0.0°C | K21: =K7 -> 0.0°C | L21: =L7 -> 0.0°C | M21: =M7 -> 0.0°C | N21: =N7 -> 0.0°C | ... P21: =P7 -> 0.0°C
B22: Fuente de incertidumbre | C22: Símbolo | D22: Distrib. | E22: Divisor | F22: Coef. ci | G22: p1 (%) | H22: p2 (%) | I22: p3 (%) | J22: p4 (%) | K22: p5 (%) | L22: p6 (%) | M22: p7 (%) | N22: p8 (%) | O22: p9 (%) | P22: p10 (%)
B23: Resolución del patrón | C23: u(dPd) | D23: Rectang. | E23: =SQRT(12) -> 3.4641016 | F23: 1 | G23: {=IFERROR(ABS(G9)/SUM(ABS('kU(E)'!$G$9:$G$16)),0)} -> 0.0035492442 | H23: {=IFERROR(ABS(H9)/SUM(ABS('kU(E)'!$H$9:$H$16)),0)} -> 0.0035492442 | I23: {=IFERROR(ABS(I9)/SUM(ABS('kU(E)'!$I$9:$I$16)),0)} -> 0.0035492442 | J23: {=IFERROR(ABS(J9)/SUM(ABS('kU(E)'!$J$9:$J$16)),0)} -> 0.0035492442 | K23: {=IFERROR(ABS(K9)/SUM(ABS('kU(E)'!$K$9:$K$16)),0)} -> 0.0035492442 | L23: {=IFERROR(ABS(L9)/SUM(ABS('kU(E)'!$L$9:$L$16)),0)} -> 0.0035492442 | M23: {=IFERROR(ABS(M9)/SUM(ABS('kU(E)'!$M$9:$M$16)),0)} -> 0.0035492442 | N23: {=IFERROR(ABS(N9)/SUM(ABS('kU(E)'!$N$9:$N$16)),0)} -> 0.0035492442 | O23: {=IFERROR(ABS(O9)/SUM(ABS('kU(E)'!$O$9:$O$16)),0)} -> 0.0035492442 | P23: =IFERROR(ABS(P9)/SUM(ABS('kU(E)'!$B9:$P16)),0) -> 0
B24: Incertidumbre calibración del patron | C24: u(dPref.) | D24: Normal2 | E24: 2 | F24: 1 | G24: {=IFERROR(ABS(G10)/SUM(ABS('kU(E)'!$G$9:$G$16)),0)} -> 0.12294942 | H24: {=IFERROR(ABS(H10)/SUM(ABS('kU(E)'!$H$9:$H$16)),0)} -> 0.12294942 | I24: {=IFERROR(ABS(I10)/SUM(ABS('kU(E)'!$I$9:$I$16)),0)} -> 0.12294942 | J24: {=IFERROR(ABS(J10)/SUM(ABS('kU(E)'!$J$9:$J$16)),0)} -> 0.12294942 | K24: {=IFERROR(ABS(K10)/SUM(ABS('kU(E)'!$K$9:$K$16)),0)} -> 0.12294942 | L24: {=IFERROR(ABS(L10)/SUM(ABS('kU(E)'!$L$9:$L$16)),0)} -> 0.12294942 | M24: {=IFERROR(ABS(M10)/SUM(ABS('kU(E)'!$M$9:$M$16)),0)} -> 0.12294942 | N24: {=IFERROR(ABS(N10)/SUM(ABS('kU(E)'!$N$9:$N$16)),0)} -> 0.12294942 | O24: {=IFERROR(ABS(O10)/SUM(ABS('kU(E)'!$O$9:$O$16)),0)} -> 0.12294942 | P24: =IFERROR(ABS(P10)/SUM(ABS('kU(E)'!$B9:$P16)),0) -> 0
B25: Interpolación corrección del patrón | C25: u(dPint.) | D25: Triangular | E25: =SQRT(6) -> 2.4494897 | F25: 1 | G25: {=IFERROR(ABS(G11)/SUM(ABS('kU(E)'!$G$9:$G$16)),0)} -> 0.010118076 | H25: {=IFERROR(ABS(H11)/SUM(ABS('kU(E)'!$H$9:$H$16)),0)} -> 0.010118076 | I25: {=IFERROR(ABS(I11)/SUM(ABS('kU(E)'!$I$9:$I$16)),0)} -> 0.010118076 | J25: {=IFERROR(ABS(J11)/SUM(ABS('kU(E)'!$J$9:$J$16)),0)} -> 0.010118076 | K25: {=IFERROR(ABS(K11)/SUM(ABS('kU(E)'!$K$9:$K$16)),0)} -> 0.010118076 | L25: {=IFERROR(ABS(L11)/SUM(ABS('kU(E)'!$L$9:$L$16)),0)} -> 0.010118076 | M25: {=IFERROR(ABS(M11)/SUM(ABS('kU(E)'!$M$9:$M$16)),0)} -> 0.010118076 | N25: {=IFERROR(ABS(N11)/SUM(ABS('kU(E)'!$N$9:$N$16)),0)} -> 0.010118076 | O25: {=IFERROR(ABS(O11)/SUM(ABS('kU(E)'!$O$9:$O$16)),0)} -> 0.010118076 | P25: =IFERROR(ABS(P11)/SUM(ABS('kU(E)'!$B9:$P16)),0) -> 0
B26: Deriva patrón | C26: u(dPder.) | D26: Rectang. | E26: =SQRT(3) -> 1.7320508 | F26: 1 | G26: {=IFERROR(ABS(G12)/SUM(ABS('kU(E)'!$G$9:$G$16)),0)} -> 0.0071953399 | H26: {=IFERROR(ABS(H12)/SUM(ABS('kU(E)'!$H$9:$H$16)),0)} -> 0.0071953399 | I26: {=IFERROR(ABS(I12)/SUM(ABS('kU(E)'!$I$9:$I$16)),0)} -> 0.0071953399 | J26: {=IFERROR(ABS(J12)/SUM(ABS('kU(E)'!$J$9:$J$16)),0)} -> 0.0071953399 | K26: {=IFERROR(ABS(K12)/SUM(ABS('kU(E)'!$K$9:$K$16)),0)} -> 0.0071953399 | L26: {=IFERROR(ABS(L12)/SUM(ABS('kU(E)'!$L$9:$L$16)),0)} -> 0.0071953399 | M26: {=IFERROR(ABS(M12)/SUM(ABS('kU(E)'!$M$9:$M$16)),0)} -> 0.0071953399 | N26: {=IFERROR(ABS(N12)/SUM(ABS('kU(E)'!$N$9:$N$16)),0)} -> 0.0071953399 | O26: {=IFERROR(ABS(O12)/SUM(ABS('kU(E)'!$O$9:$O$16)),0)} -> 0.0071953399 | P26: =IFERROR(ABS(P12)/SUM(ABS('kU(E)'!$B9:$P16)),0) -> 0
B27: Caracerisiticas medio isotermo | C27: u(δMiso) | D27: Rectang. | E27: =SQRT(3) -> 1.7320508 | F27: 1 | G27: {=IFERROR(ABS(G13)/SUM(ABS('kU(E)'!$G$9:$G$16)),0)} -> 0.14633909 | H27: {=IFERROR(ABS(H13)/SUM(ABS('kU(E)'!$H$9:$H$16)),0)} -> 0.14633909 | I27: {=IFERROR(ABS(I13)/SUM(ABS('kU(E)'!$I$9:$I$16)),0)} -> 0.14633909 | J27: {=IFERROR(ABS(J13)/SUM(ABS('kU(E)'!$J$9:$J$16)),0)} -> 0.14633909 | K27: {=IFERROR(ABS(K13)/SUM(ABS('kU(E)'!$K$9:$K$16)),0)} -> 0.14633909 | L27: {=IFERROR(ABS(L13)/SUM(ABS('kU(E)'!$L$9:$L$16)),0)} -> 0.14633909 | M27: {=IFERROR(ABS(M13)/SUM(ABS('kU(E)'!$M$9:$M$16)),0)} -> 0.14633909 | N27: {=IFERROR(ABS(N13)/SUM(ABS('kU(E)'!$N$9:$N$16)),0)} -> 0.14633909 | O27: {=IFERROR(ABS(O13)/SUM(ABS('kU(E)'!$O$9:$O$16)),0)} -> 0.14633909 | P27: =IFERROR(ABS(P13)/SUM(ABS('kU(E)'!$B9:$P16)),0) -> 0
B28: Resolución del instrumento | C28: u(δTd) | D28: Rectang. | E28: =2*SQRT(3) -> 3.4641016 | F28: 1 | G28: {=IFERROR(ABS(G14)/SUM(ABS('kU(E)'!$G$9:$G$16)),0)} -> 0.70984883 | H28: {=IFERROR(ABS(H14)/SUM(ABS('kU(E)'!$H$9:$H$16)),0)} -> 0.70984883 | I28: {=IFERROR(ABS(I14)/SUM(ABS('kU(E)'!$I$9:$I$16)),0)} -> 0.70984883 | J28: {=IFERROR(ABS(J14)/SUM(ABS('kU(E)'!$J$9:$J$16)),0)} -> 0.70984883 | K28: {=IFERROR(ABS(K14)/SUM(ABS('kU(E)'!$K$9:$K$16)),0)} -> 0.70984883 | L28: {=IFERROR(ABS(L14)/SUM(ABS('kU(E)'!$L$9:$L$16)),0)} -> 0.70984883 | M28: {=IFERROR(ABS(M14)/SUM(ABS('kU(E)'!$M$9:$M$16)),0)} -> 0.70984883 | N28: {=IFERROR(ABS(N14)/SUM(ABS('kU(E)'!$N$9:$N$16)),0)} -> 0.70984883 | O28: {=IFERROR(ABS(O14)/SUM(ABS('kU(E)'!$O$9:$O$16)),0)} -> 0.70984883 | P28: =IFERROR(ABS(P14)/SUM(ABS('kU(E)'!$B9:$P16)),0) -> 0
B29: Repetibilidad del instrumento | C29: u(Trep) | D29: Rectang. | E29: =SQRT(3) -> 1.7320508 | F29: 1 | G29: {=IFERROR(ABS(G15)/SUM(ABS('kU(E)'!$G$9:$G$16)),0)} -> 0 | H29: {=IFERROR(ABS(H15)/SUM(ABS('kU(E)'!$H$9:$H$16)),0)} -> 0 | I29: {=IFERROR(ABS(I15)/SUM(ABS('kU(E)'!$I$9:$I$16)),0)} -> 0 | J29: {=IFERROR(ABS(J15)/SUM(ABS('kU(E)'!$J$9:$J$16)),0)} -> 0 | K29: {=IFERROR(ABS(K15)/SUM(ABS('kU(E)'!$K$9:$K$16)),0)} -> 0 | L29: {=IFERROR(ABS(L15)/SUM(ABS('kU(E)'!$L$9:$L$16)),0)} -> 0 | M29: {=IFERROR(ABS(M15)/SUM(ABS('kU(E)'!$M$9:$M$16)),0)} -> 0 | N29: {=IFERROR(ABS(N15)/SUM(ABS('kU(E)'!$N$9:$N$16)),0)} -> 0 | O29: {=IFERROR(ABS(O15)/SUM(ABS('kU(E)'!$O$9:$O$16)),0)} -> 0 | P29: =IFERROR(ABS(P15)/SUM(ABS('kU(E)'!$B9:$P16)),0) -> 0
B30: Influencia ambiental | C30: u(dPt) | D30: Rectang. | E30: =SQRT(3) -> 1.7320508 | F30: 1 | G30: {=IFERROR(ABS(G16)/SUM(ABS('kU(E)'!$G$9:$G$16)),0)} -> 0 | H30: {=IFERROR(ABS(H16)/SUM(ABS('kU(E)'!$H$9:$H$16)),0)} -> 0 | I30: {=IFERROR(ABS(I16)/SUM(ABS('kU(E)'!$I$9:$I$16)),0)} -> 0 | J30: {=IFERROR(ABS(J16)/SUM(ABS('kU(E)'!$J$9:$J$16)),0)} -> 0 | K30: {=IFERROR(ABS(K16)/SUM(ABS('kU(E)'!$K$9:$K$16)),0)} -> 0 | L30: {=IFERROR(ABS(L16)/SUM(ABS('kU(E)'!$L$9:$L$16)),0)} -> 0 | M30: {=IFERROR(ABS(M16)/SUM(ABS('kU(E)'!$M$9:$M$16)),0)} -> 0 | N30: {=IFERROR(ABS(N16)/SUM(ABS('kU(E)'!$N$9:$N$16)),0)} -> 0 | O30: {=IFERROR(ABS(O16)/SUM(ABS('kU(E)'!$O$9:$O$16)),0)} -> 0 | P30: =IFERROR(ABS(P16)/SUM(ABS('kU(E)'!$B9:$P16)),0) -> 0
B31: Contribuciones incert. combinada | G31: =SUBTOTAL(109,tblUcomun10[p1 (%)]) -> 1 | H31: =SUBTOTAL(109,tblUcomun10[p2 (%)]) -> 1 | I31: =SUBTOTAL(109,tblUcomun10[p3 (%)]) -> 1 | J31: =SUBTOTAL(109,tblUcomun10[p4 (%)]) -> 1 | K31: =SUBTOTAL(109,tblUcomun10[p5 (%)]) -> 1 | L31: =SUBTOTAL(109,tblUcomun10[p6 (%)]) -> 1 | M31: =SUBTOTAL(109,tblUcomun10[p7 (%)]) -> 1 | N31: =SUBTOTAL(109,tblUcomun10[p8 (%)]) -> 1 | O31: =SUBTOTAL(109,tblUcomun10[p9 (%)]) -> 1 | P31: =SUBTOTAL(109,tblUcomun10[p10 (%)]) -> 0
B35: Cálculo grados efectivos de libertad
B36: Descripción | C36: Variable | E36: Formula | F36: Valor
B37: Cantidad mediciones | C37: n | E37: - | F37: =COUNT(Calibración!D15,Calibración!F15,Calibración!H15) -> 3
B38: Grados libertad | C38: vi | E38: n-1 | F38: =F37-1 -> 2
B39: Incertidumbre estandar | C39: ui(y)=u(δIrep) | E39: s(xi)/Ön | F39: ® | G39: =G15 -> 0 | H39: =H15 -> 0 | I39: =I15 -> 0 | J39: =J15 -> 0 | K39: =K15 -> 0 | L39: =L15 -> 0 | M39: =M15 -> 0 | N39: =N15 -> 0 | ... P39: =P15 -> 0
B40: Incertidumbre combinada punto 1 | C40: uc4(y) | F40: =POWER('kU(E)'!$G$17,4) -> 1.2788513e-05 | G40: u14/vi | H40: u24/vi | I40: u34/vi | J40: u44/vi | K40: u54/vi | L40: u64/vi | M40: u74/vi | N40: u84/vi | O40: u94/vi | P40: u104/vi
B41: Incertidumbre combinada punto 2 | C41: uc4(y) | F41: =POWER('kU(E)'!$H$17,4) -> 1.2788513e-05 | G41: =IFERROR(POWER(G15,4)/$F$38,"") -> 0 | H41: =IFERROR(POWER(H15,4)/$F$38,"") -> 0 | I41: =IFERROR(POWER(I15,4)/$F$38,"") -> 0 | J41: =IFERROR(POWER(J15,4)/$F$38,"") -> 0 | K41: =IFERROR(POWER(K15,4)/$F$38,"") -> 0 | L41: =IFERROR(POWER(L15,4)/$F$38,"") -> 0 | M41: =IFERROR(POWER(M15,4)/$F$38,"") -> 0 | N41: =IFERROR(POWER(N15,4)/$F$38,"") -> 0 | ... P41: =IFERROR(POWER(P15,4)/$F$38,"") -> 0
B42: Incertidumbre combinada punto 3 | C42: uc4(y) | F42: =POWER('kU(E)'!$I$17,4) -> 1.2788513e-05
B43: Incertidumbre combinada punto 4 | C43: uc4(y) | F43: =POWER('kU(E)'!$J$17,4) -> 1.2788513e-05
B44: Incertidumbre combinada punto 5 | C44: uc4(y) | F44: =POWER('kU(E)'!$K$17,4) -> 1.2788513e-05
B45: Incertidumbre combinada punto 6 | C45: uc4(y) | F45: =POWER('kU(E)'!$L$17,4) -> 1.2788513e-05
B46: Incertidumbre combinada punto 7 | C46: uc4(y) | F46: =POWER('kU(E)'!$M$17,4) -> 1.2788513e-05
B47: Incertidumbre combinada punto 8 | C47: uc4(y) | F47: =POWER('kU(E)'!$N$17,4) -> 1.2788513e-05
B48: Incertidumbre combinada punto 9 | C48: uc4(y) | F48: =POWER('kU(E)'!$O$17,4) -> 1.2788513e-05
...

Sheet Calibración
C1: K = °C + 273,15 | G1: 1K=1oC
C2: K=C= 5(°F + 459,67) /9 = (°F + 459,67) / 1,8 | G2: 1K=5oF/9 | M2: Características medio isotermo (Pozo seco NI-MCPT-37) | S2: Determinación intervalos de medida de certificados
L3: Componente incertidumbre | P3: Especificación fabricante [oC] | Q3: Incertidubre Estandar [oC] | S3: Patrón | U3: tmin [oC] | V3: tmax [oC]
C4: Datos del equipo calibración | H4: Datos del patrón | L4: Histeresis | P4: 0.025 | Q4: =Histeresis/SQRT(3) -> 0.014433757 | S4: NI-MCPT-37 | U4: =IFERROR(VLOOKUP(S4,tblBD_PatronTerm[[Código Patrón]:[max.]],8,FALSE),"") -> -30 | V4: =IFERROR(VLOOKUP(S4,tblBD_PatronTerm[[Código Patrón]:[max.]],9,FALSE),"") -> 155
C5: Division de escala | F5: 0.2 | H5: Patrón utilizado | J5: NI-MCPT-05 | L5: Uniformidad axial | P5: 0.02 | Q5: =P5/SQRT(3) -> 0.011547005 | S5: =J5 -> NI-MCPT-05 | U5: =IFERROR(VLOOKUP(S5,tblBD_PatronTerm[[Código Patrón]:[max.]],8,FALSE),"") -> -30 | V5: =IFERROR(VLOOKUP(S5,tblBD_PatronTerm[[Código Patrón]:[max.]],9,FALSE),"") -> 250
C6: Rango de medida (min.|max.) | F6: =RangoMedida -> 0 | H6: Resolución patrón | J6: =IFERROR(VLOOKUP(J5,tblBD_PatronTerm[[Código Patrón]:[Fecha calib.]],12,FALSE),"") -> 0.001 | L6: Uniformidad radial | P6: 0.01 | Q6: =P6/SQRT(3) -> 0.0057735027
C7: Unidad de medida | E7: =IF(unidad="°C",0,IF(unidad="°F",32,273.15)) -> 0 | F7: °C | L7: Estabilidad | P7: 0.005 | Q7: =P7/SQRT(3) -> 0.0028867513 | S7: Coeficiente de temperatura kt%[%]/100*Medición[oC]+ktºC[oC]
C8: Tipo de sonda | F8: RTD | L8: Efecto de carga | P8: 0.005 | Q8: =P8/SQRT(3) -> 0.0028867513 | S8: Patrón | U8: tmin [oC] | V8: tmax [oC] | W8: kt% [%] | X8: ktºC [oC]
E9: Decim.: | F9: =LEN(MOD(ABS(ResolTerm),1))-1-(MOD(ResolTerm,1)>0) -> 1 | L9: Gradiente | P9: 0.01 | Q9: =P9/SQRT(3) -> 0.0057735027 | S9: =S4 -> NI-MCPT-37 | U9: =IFERROR(LOOKUP(S9,tblBD_PatronTerm[Código Patrón],tblBD_PatronTerm[t min]),"") -> -40 | V9: =IFERROR(LOOKUP(S9,tblBD_PatronTerm[Código Patrón],tblBD_PatronTerm[t max]),"") -> 140 | W9: =IFERROR(VLOOKUP(S9,tblBD_PatronTerm[[Código Patrón]:[Certificado]],13,FALSE),"") -> 0 | X9: =IFERROR(VLOOKUP(S9,tblBD_PatronTerm[[Código Patrón]:[Certificado]],14,FALSE),"") -> 0
L10: Incertidumbre combinada med. Isotermo | Q10: =IFERROR(SQRT(SUMSQ(Q4:Q9)),"") -> 0.020615528 | S10: =IF(S4=S5,"",J5) -> NI-MCPT-05 | U10: =IFERROR(LOOKUP(S10,tblBD_PatronTerm[Código Patrón],tblBD_PatronTerm[t min]),"") -> 16 | V10: =IFERROR(LOOKUP(S10,tblBD_PatronTerm[Código Patrón],tblBD_PatronTerm[t max]),"") -> 30 | W10: =IFERROR(VLOOKUP(S10,tblBD_PatronTerm[[Código Patrón]:[Certificado]],13,FALSE),"") -> 0.00385 | X10: =IFERROR(VLOOKUP(S10,tblBD_PatronTerm[[Código Patrón]:[Certificado]],14,FALSE),"") -> 0
B13: Linealidad | F13: =CONCATENATE("Todo en [",unidad,"]") -> Todo en [°C] | I13: Repetibilidad | N13: =CONCATENATE("Todo en [",unidad,"]") -> Todo en [°C] | O13: Interpolación | S13: Interpolación | T13: Interpolación
B14: # | C14: Patrón | D14: Equipo | E14: Patrón | F14: Equipo | G14: Patrón | H14: Equipo | I14: Patrón | J14: Equipo | K14: Desviación estándar | M14: # | N14: Promedio Patrón | O14: Corrección patrón | P14: Patrón corregido | Q14: Promedio equipo | R14: Corrección de medición | S14: Incertid. patrón | T14: Deriva patrón | U14: Exactitud cond.termicas 1er. Patron | V14: Exactitud cond.termicas 2do. Patron
B15: 1 | C15: ='NI-R01-MCIT-T-01'!B24 -> 0 | D15: ='NI-R01-MCIT-T-01'!C24 -> 0 | E15: ='NI-R01-MCIT-T-01'!D24 -> 0 | F15: ='NI-R01-MCIT-T-01'!E24 -> 0 | G15: ='NI-R01-MCIT-T-01'!F24 -> 0 | H15: ='NI-R01-MCIT-T-01'!G24 -> 0 | I15: =IFERROR(AVERAGE(C15,E15,G15),"") -> 0 | J15: =IFERROR(AVERAGE(D15,F15,H15),"") -> 0 | K15: =IFERROR(IF(C15="","",_xlfn.STDEV.S(D15,F15,H15)),"") -> 0 | M15: 1 | N15: =IFERROR(AVERAGE(C15,E15,G15),"") -> 0 | O15: =IF(tblResultCalib[[#This Row],[Promedio Patrón]]="","",IFERROR(IF(coef_unidad=32,(OFFSET($V$36,0,tblResultCalib[[#This Row],['#]]-1)),OFFSET($V$36,0,tblResultCalib[[#This Row],['#]]-1)+coef_unidad),TREND($O$31:OFFSET($O$31,NumPuntosCalib-1,0),$N$31:OFFSET($N$31,NumPuntosCalib-1,0),tblResultCalib[[#This Row],[Promedio Patrón]]))) -> -0.0020157983 | P15: =IFERROR(tblResultCalib[[#This Row],[Promedio Patrón]]+tblResultCalib[[#This Row],[Corrección patrón]],"") -> -0.0020157983 | Q15: =IFERROR(J15,"") -> 0 | R15: =IFERROR(tblResultCalib[[#This Row],[Patrón corregido]]-tblResultCalib[[#This Row],[Promedio equipo]],"") -> -0.0020157983 | S15: =IF(tblResultCalib[[#This Row],[Promedio Patrón]]="","",IFERROR(IF(coef_unidad=32,(OFFSET($V$47,0,tblResultCalib[[#This Row],['#]]-1)),OFFSET($V$47,0,tblResultCalib[[#This Row],['#]]-1)+coef_unidad),TREND($P$31:OFFSET($P$31,NumPuntosCalib-1,0),$N$31:OFFSET($N$31,NumPuntosCalib-1,0),tblResultCalib[[#This Row],[Promedio Patrón]]))) -> 0.02 | T15: =IF(tblResultCalib[[#This Row],[Promedio Patrón]]="","",IFERROR(IF(coef_unidad=32,(OFFSET($V$58,0,tblResultCalib[[#This Row],['#]]-1)),OFFSET($V$58,0,tblResultCalib[[#This Row],['#]]-1)+coef_unidad),TREND($Q$31:OFFSET($Q$31,NumPuntosCalib-1,0),$N$31:OFFSET($N$31,NumPuntosCalib-1,0),tblResultCalib[[#This Row],[Promedio Patrón]]))) -> 0.001013644 | U15: =IFERROR(ABS(IF(OR(CertTempC<Calibración!$U$9,CertTempC>Calibración!$V$9),tblResultCalib[[#This Row],[Promedio Patrón]]*Calibración!$W$9/100+Calibración!$X$9,0)),"") -> 0 | V15: =IFERROR(ABS(IF(OR(CertTempC<Calibración!$U$10,CertTempC>Calibración!$V$10),tblResultCalib[[#This Row],[Promedio Patrón]]*Calibración!$W$10/100+Calibración!$X$10,0)),"") -> 0
B16: 2 | C16: ='NI-R01-MCIT-T-01'!B25 -> 0 | D16: ='NI-R01-MCIT-T-01'!C25 -> 0 | E16: ='NI-R01-MCIT-T-01'!D25 -> 0 | F16: ='NI-R01-MCIT-T-01'!E25 -> 0 | G16: ='NI-R01-MCIT-T-01'!F25 -> 0 | H16: ='NI-R01-MCIT-T-01'!G25 -> 0 | I16: =IFERROR(AVERAGE(C16,E16,G16),"") -> 0 | J16: =IFERROR(AVERAGE(D16,F16,H16),"") -> 0 | K16: =IFERROR(IF(C16="","",_xlfn.STDEV.S(D16,F16,H16)),"") -> 0 | M16: 2 | N16: =IFERROR(AVERAGE(C16,E16,G16),"") -> 0 | O16: =IF(tblResultCalib[[#This Row],[Promedio Patrón]]="","",IFERROR(IF(coef_unidad=32,(OFFSET($V$36,0,tblResultCalib[[#This Row],['#]]-1)),OFFSET($V$36,0,tblResultCalib[[#This Row],['#]]-1)+coef_unidad),TREND($O$31:OFFSET($O$31,NumPuntosCalib-1,0),$N$31:OFFSET($N$31,NumPuntosCalib-1,0),tblResultCalib[[#This Row],[Promedio Patrón]]))) -> -0.0020157983 | P16: =IFERROR(tblResultCalib[[#This Row],[Promedio Patrón]]+tblResultCalib[[#This Row],[Corrección patrón]],"") -> -0.0020157983 | Q16: =IFERROR(J16,"") -> 0 | R16: =IFERROR(tblResultCalib[[#This Row],[Patrón corregido]]-tblResultCalib[[#This Row],[Promedio equipo]],"") -> -0.0020157983 | S16: =IF(tblResultCalib[[#This Row],[Promedio Patrón]]="","",IFERROR(IF(coef_unidad=32,(OFFSET($V$47,0,tblResultCalib[[#This Row],['#]]-1)),OFFSET($V$47,0,tblResultCalib[[#This Row],['#]]-1)+coef_unidad),TREND($P$31:OFFSET($P$31,NumPuntosCalib-1,0),$N$31:OFFSET($N$31,NumPuntosCalib-1,0),tblResultCalib[[#This Row],[Promedio Patrón]]))) -> 0.02 | T16: =IF(tblResultCalib[[#This Row],[Promedio Patrón]]="","",IFERROR(IF(coef_unidad=32,(OFFSET($V$58,0,tblResultCalib[[#This Row],['#]]-1)),OFFSET($V$58,0,tblResultCalib[[#This Row],['#]]-1)+coef_unidad),TREND($Q$31:OFFSET($Q$31,NumPuntosCalib-1,0),$N$31:OFFSET($N$31,NumPuntosCalib-1,0),tblResultCalib[[#This Row],[Promedio Patrón]]))) -> 0.001013644 | U16: =IFERROR(ABS(IF(OR(CertTempC<Calibración!$U$9,CertTempC>Calibración!$V$9),tblResultCalib[[#This Row],[Promedio Patrón]]*Calibración!$W$9/100+Calibración!$X$9,0)),"") -> 0 | V16: =IFERROR(ABS(IF(OR(CertTempC<Calibración!$U$10,CertTempC>Calibración!$V$10),tblResultCalib[[#This Row],[Promedio Patrón]]*Calibración!$W$10/100+Calibración!$X$10,0)),"") -> 0
B17: 3 | C17: ='NI-R01-MCIT-T-01'!B26 -> 0 | D17: ='NI-R01-MCIT-T-01'!C26 -> 0 | E17: ='NI-R01-MCIT-T-01'!D26 -> 0 | F17: ='NI-R01-MCIT-T-01'!E26 -> 0 | G17: ='NI-R01-MCIT-T-01'!F26 -> 0 | H17: ='NI-R01-MCIT-T-01'!G26 -> 0 | I17: =IFERROR(AVERAGE(C17,E17,G17),"") -> 0 | J17: =IFERROR(AVERAGE(D17,F17,H17),"") -> 0 | K17: =IFERROR(IF(C17="","",_xlfn.STDEV.S(D17,F17,H17)),"") -> 0 | M17: 3 | N17: =IFERROR(AVERAGE(C17,E17,G17),"") -> 0 | O17: =IF(tblResultCalib[[#This Row],[Promedio Patrón]]="","",IFERROR(IF(coef_unidad=32,(OFFSET($V$36,0,tblResultCalib[[#This Row],['#]]-1)),OFFSET($V$36,0,tblResultCalib[[#This Row],['#]]-1)+coef_unidad),TREND($O$31:OFFSET($O$31,NumPuntosCalib-1,0),$N$31:OFFSET($N$31,NumPuntosCalib-1,0),tblResultCalib[[#This Row],[Promedio Patrón]]))) -> -0.0020157983 | P17: =IFERROR(tblResultCalib[[#This Row],[Promedio Patrón]]+tblResultCalib[[#This Row],[Corrección patrón]],"") -> -0.0020157983 | Q17: =IFERROR(J17,"") -> 0 | R17: =IFERROR(tblResultCalib[[#This Row],[Patrón corregido]]-tblResultCalib[[#This Row],[Promedio equipo]],"") -> -0.0020157983 | S17: =IF(tblResultCalib[[#This Row],[Promedio Patrón]]="","",IFERROR(IF(coef_unidad=32,(OFFSET($V$47,0,tblResultCalib[[#This Row],['#]]-1)),OFFSET($V$47,0,tblResultCalib[[#This Row],['#]]-1)+coef_unidad),TREND($P$31:OFFSET($P$31,NumPuntosCalib-1,0),$N$31:OFFSET($N$31,NumPuntosCalib-1,0),tblResultCalib[[#This Row],[Promedio Patrón]]))) -> 0.02 | T17: =IF(tblResultCalib[[#This Row],[Promedio Patrón]]="","",IFERROR(IF(coef_unidad=32,(OFFSET($V$58,0,tblResultCalib[[#This Row],['#]]-1)),OFFSET($V$58,0,tblResultCalib[[#This Row],['#]]-1)+coef_unidad),TREND($Q$31:OFFSET($Q$31,NumPuntosCalib-1,0),$N$31:OFFSET($N$31,NumPuntosCalib-1,0),tblResultCalib[[#This Row],[Promedio Patrón]]))) -> 0.001013644 | U17: =IFERROR(ABS(IF(OR(CertTempC<Calibración!$U$9,CertTempC>Calibración!$V$9),tblResultCalib[[#This Row],[Promedio Patrón]]*Calibración!$W$9/100+Calibración!$X$9,0)),"") -> 0 | V17: =IFERROR(ABS(IF(OR(CertTempC<Calibración!$U$10,CertTempC>Calibración!$V$10),tblResultCalib[[#This Row],[Promedio Patrón]]*Calibración!$W$10/100+Calibración!$X$10,0)),"") -> 0
B18: 4 | C18: ='NI-R01-MCIT-T-01'!B27 -> 0 | D18: ='NI-R01-MCIT-T-01'!C27 -> 0 | E18: ='NI-R01-MCIT-T-01'!D27 -> 0 | F18: ='NI-R01-MCIT-T-01'!E27 -> 0 | G18: ='NI-R01-MCIT-T-01'!F27 -> 0 | H18: ='NI-R01-MCIT-T-01'!G27 -> 0 | I18: =IFERROR(AVERAGE(C18,E18,G18),"") -> 0 | J18: =IFERROR(AVERAGE(D18,F18,H18),"") -> 0 | K18: =IFERROR(IF(C18="","",_xlfn.STDEV.S(D18,F18,H18)),"") -> 0 | M18: 4 | N18: =IFERROR(AVERAGE(C18,E18,G18),"") -> 0 | O18: =IF(tblResultCalib[[#This Row],[Promedio Patrón]]="","",IFERROR(IF(coef_unidad=32,(OFFSET($V$36,0,tblResultCalib[[#This Row],['#]]-1)),OFFSET($V$36,0,tblResultCalib[[#This Row],['#]]-1)+coef_unidad),TREND($O$31:OFFSET($O$31,NumPuntosCalib-1,0),$N$31:OFFSET($N$31,NumPuntosCalib-1,0),tblResultCalib[[#This Row],[Promedio Patrón]]))) -> -0.0020157983 | P18: =IFERROR(tblResultCalib[[#This Row],[Promedio Patrón]]+tblResultCalib[[#This Row],[Corrección patrón]],"") -> -0.0020157983 | Q18: =IFERROR(J18,"") -> 0 | R18: =IFERROR(tblResultCalib[[#This Row],[Patrón corregido]]-tblResultCalib[[#This Row],[Promedio equipo]],"") -> -0.0020157983 | S18: =IF(tblResultCalib[[#This Row],[Promedio Patrón]]="","",IFERROR(IF(coef_unidad=32,(OFFSET($V$47,0,tblResultCalib[[#This Row],['#]]-1)),OFFSET($V$47,0,tblResultCalib[[#This Row],['#]]-1)+coef_unidad),TREND($P$31:OFFSET($P$31,NumPuntosCalib-1,0),$N$31:OFFSET($N$31,NumPuntosCalib-1,0),tblResultCalib[[#This Row],[Promedio Patrón]]))) -> 0.02 | T18: =IF(tblResultCalib[[#This Row],[Promedio Patrón]]="","",IFERROR(IF(coef_unidad=32,(OFFSET($V$58,0,tblResultCalib[[#This Row],['#]]-1)),OFFSET($V$58,0,tblResultCalib[[#This Row],['#]]-1)+coef_unidad),TREND($Q$31:OFFSET($Q$31,NumPuntosCalib-1,0),$N$31:OFFSET($N$31,NumPuntosCalib-1,0),tblResultCalib[[#This Row],[Promedio Patrón]]))) -> 0.001013644 | U18: =IFERROR(ABS(IF(OR(CertTempC<Calibración!$U$9,CertTempC>Calibración!$V$9),tblResultCalib[[#This Row],[Promedio Patrón]]*Calibración!$W$9/100+Calibración!$X$9,0)),"") -> 0 | V18: =IFERROR(ABS(IF(OR(CertTempC<Calibración!$U$10,CertTempC>Calibración!$V$10),tblResultCalib[[#This Row],[Promedio Patrón]]*Calibración!$W$10/100+Calibración!$X$10,0)),"") -> 0
B19: 5 | C19: ='NI-R01-MCIT-T-01'!B28 -> 0 | D19: ='NI-R01-MCIT-T-01'!C28 -> 0 | E19: ='NI-R01-MCIT-T-01'!D28 -> 0 | F19: ='NI-R01-MCIT-T-01'!E28 -> 0 | G19: ='NI-R01-MCIT-T-01'!F28 -> 0 | H19: ='NI-R01-MCIT-T-01'!G28 -> 0 | I19: =IFERROR(AVERAGE(C19,E19,G19),"") -> 0 | J19: =IFERROR(AVERAGE(D19,F19,H19),"") -> 0 | K19: =IFERROR(IF(C19="","",_xlfn.STDEV.S(D19,F19,H19)),"") -> 0 | M19: 5 | N19: =IFERROR(AVERAGE(C19,E19,G19),"") -> 0 | O19: =IF(tblResultCalib[[#This Row],[Promedio Patrón]]="","",IFERROR(IF(coef_unidad=32,(OFFSET($V$36,0,tblResultCalib[[#This Row],['#]]-1)),OFFSET($V$36,0,tblResultCalib[[#This Row],['#]]-1)+coef_unidad),TREND($O$31:OFFSET($O$31,NumPuntosCalib-1,0),$N$31:OFFSET($N$31,NumPuntosCalib-1,0),tblResultCalib[[#This Row],[Promedio Patrón]]))) -> -0.0020157983 | P19: =IFERROR(tblResultCalib[[#This Row],[Promedio Patrón]]+tblResultCalib[[#This Row],[Corrección patrón]],"") -> -0.0020157983 | Q19: =IFERROR(J19,"") -> 0 | R19: =IFERROR(tblResultCalib[[#This Row],[Patrón corregido]]-tblResultCalib[[#This Row],[Promedio equipo]],"") -> -0.0020157983 | S19: =IF(tblResultCalib[[#This Row],[Promedio Patrón]]="","",IFERROR(IF(coef_unidad=32,(OFFSET($V$47,0,tblResultCalib[[#This Row],['#]]-1)),OFFSET($V$47,0,tblResultCalib[[#This Row],['#]]-1)+coef_unidad),TREND($P$31:OFFSET($P$31,NumPuntosCalib-1,0),$N$31:OFFSET($N$31,NumPuntosCalib-1,0),tblResultCalib[[#This Row],[Promedio Patrón]]))) -> 0.02 | T19: =IF(tblResultCalib[[#This Row],[Promedio Patrón]]="","",IFERROR(IF(coef_unidad=32,(OFFSET($V$58,0,tblResultCalib[[#This Row],['#]]-1)),OFFSET($V$58,0,tblResultCalib[[#This Row],['#]]-1)+coef_unidad),TREND($Q$31:OFFSET($Q$31,NumPuntosCalib-1,0),$N$31:OFFSET($N$31,NumPuntosCalib-1,0),tblResultCalib[[#This Row],[Promedio Patrón]]))) -> 0.001013644 | U19: =IFERROR(ABS(IF(OR(CertTempC<Calibración!$U$9,CertTempC>Calibración!$V$9),tblResultCalib[[#This Row],[Promedio Patrón]]*Calibración!$W$9/100+Calibración!$X$9,0)),"") -> 0 | V19: =IFERROR(ABS(IF(OR(CertTempC<Calibración!$U$10,CertTempC>Calibración!$V$10),tblResultCalib[[#This Row],[Promedio Patrón]]*Calibración!$W$10/100+Calibración!$X$10,0)),"") -> 0
B20: 6 | C20: ='NI-R01-MCIT-T-01'!B29 -> 0 | D20: ='NI-R01-MCIT-T-01'!C29 -> 0 | E20: ='NI-R01-MCIT-T-01'!D29 -> 0 | F20: ='NI-R01-MCIT-T-01'!E29 -> 0 | G20: ='NI-R01-MCIT-T-01'!F29 -> 0 | H20: ='NI-R01-MCIT-T-01'!G29 -> 0 | I20: =IFERROR(AVERAGE(C20,E20,G20),"") -> 0 | J20: =IFERROR(AVERAGE(D20,F20,H20),"") -> 0 | K20: =IFERROR(IF(C20="","",_xlfn.STDEV.S(D20,F20,H20)),"") -> 0 | M20: 6 | N20: =IFERROR(AVERAGE(C20,E20,G20),"") -> 0 | O20: =IF(tblResultCalib[[#This Row],[Promedio Patrón]]="","",IFERROR(IF(coef_unidad=32,(OFFSET($V$36,0,tblResultCalib[[#This Row],['#]]-1)),OFFSET($V$36,0,tblResultCalib[[#This Row],['#]]-1)+coef_unidad),TREND($O$31:OFFSET($O$31,NumPuntosCalib-1,0),$N$31:OFFSET($N$31,NumPuntosCalib-1,0),tblResultCalib[[#This Row],[Promedio Patrón]]))) -> -0.0020157983 | P20: =IFERROR(tblResultCalib[[#This Row],[Promedio Patrón]]+tblResultCalib[[#This Row],[Corrección patrón]],"") -> -0.0020157983 | Q20: =IFERROR(J20,"") -> 0 | R20: =IFERROR(tblResultCalib[[#This Row],[Patrón corregido]]-tblResultCalib[[#This Row],[Promedio equipo]],"") -> -0.0020157983 | S20: =IF(tblResultCalib[[#This Row],[Promedio Patrón]]="","",IFERROR(IF(coef_unidad=32,(OFFSET($V$47,0,tblResultCalib[[#This Row],['#]]-1)),OFFSET($V$47,0,tblResultCalib[[#This Row],['#]]-1)+coef_unidad),TREND($P$31:OFFSET($P$31,NumPuntosCalib-1,0),$N$31:OFFSET($N$31,NumPuntosCalib-1,0),tblResultCalib[[#This Row],[Promedio Patrón]]))) -> 0.02 | T20: =IF(tblResultCalib[[#This Row],[Promedio Patrón]]="","",IFERROR(IF(coef_unidad=32,(OFFSET($V$58,0,tblResultCalib[[#This Row],['#]]-1)),OFFSET($V$58,0,tblResultCalib[[#This Row],['#]]-1)+coef_unidad),TREND($Q$31:OFFSET($Q$31,NumPuntosCalib-1,0),$N$31:OFFSET($N$31,NumPuntosCalib-1,0),tblResultCalib[[#This Row],[Promedio Patrón]]))) -> 0.001013644 | U20: =IFERROR(ABS(IF(OR(CertTempC<Calibración!$U$9,CertTempC>Calibración!$V$9),tblResultCalib[[#This Row],[Promedio Patrón]]*Calibración!$W$9/100+Calibración!$X$9,0)),"") -> 0 | V20: =IFERROR(ABS(IF(OR(CertTempC<Calibración!$U$10,CertTempC>Calibración!$V$10),tblResultCalib[[#This Row],[Promedio Patrón]]*Calibración!$W$10/100+Calibración!$X$10,0)),"") -> 0
B21: 7 | C21: ='NI-R01-MCIT-T-01'!B30 -> 0 | D21: ='NI-R01-MCIT-T-01'!C30 -> 0 | E21: ='NI-R01-MCIT-T-01'!D30 -> 0 | F21: ='NI-R01-MCIT-T-01'!E30 -> 0 | G21: ='NI-R01-MCIT-T-01'!F30 -> 0 | H21: ='NI-R01-MCIT-T-01'!G30 -> 0 | I21: =IFERROR(AVERAGE(C21,E21,G21),"") -> 0 | J21: =IFERROR(AVERAGE(D21,F21,H21),"") -> 0 | K21: =IFERROR(IF(C21="","",_xlfn.STDEV.S(D21,F21,H21)),"") -> 0 | M21: 7 | N21: =IFERROR(AVERAGE(C21,E21,G21),"") -> 0 | O21: =IF(tblResultCalib[[#This Row],[Promedio Patrón]]="","",IFERROR(IF(coef_unidad=32,(OFFSET($V$36,0,tblResultCalib[[#This Row],['#]]-1)),OFFSET($V$36,0,tblResultCalib[[#This Row],['#]]-1)+coef_unidad),TREND($O$31:OFFSET($O$31,NumPuntosCalib-1,0),$N$31:OFFSET($N$31,NumPuntosCalib-1,0),tblResultCalib[[#This Row],[Promedio Patrón]]))) -> -0.0020157983 | P21: =IFERROR(tblResultCalib[[#This Row],[Promedio Patrón]]+tblResultCalib[[#This Row],[Corrección patrón]],"") -> -0.0020157983 | Q21: =IFERROR(J21,"") -> 0 | R21: =IFERROR(tblResultCalib[[#This Row],[Patrón corregido]]-tblResultCalib[[#This Row],[Promedio equipo]],"") -> -0.0020157983 | S21: =IF(tblResultCalib[[#This Row],[Promedio Patrón]]="","",IFERROR(IF(coef_unidad=32,(OFFSET($V$47,0,tblResultCalib[[#This Row],['#]]-1)),OFFSET($V$47,0,tblResultCalib[[#This Row],['#]]-1)+coef_unidad),TREND($P$31:OFFSET($P$31,NumPuntosCalib-1,0),$N$31:OFFSET($N$31,NumPuntosCalib-1,0),tblResultCalib[[#This Row],[Promedio Patrón]]))) -> 0.02 | T21: =IF(tblResultCalib[[#This Row],[Promedio Patrón]]="","",IFERROR(IF(coef_unidad=32,(OFFSET($V$58,0,tblResultCalib[[#This Row],['#]]-1)),OFFSET($V$58,0,tblResultCalib[[#This Row],['#]]-1)+coef_unidad),TREND($Q$31:OFFSET($Q$31,NumPuntosCalib-1,0),$N$31:OFFSET($N$31,NumPuntosCalib-1,0),tblResultCalib[[#This Row],[Promedio Patrón]]))) -> 0.001013644 | U21: =IFERROR(ABS(IF(OR(CertTempC<Calibración!$U$9,CertTempC>Calibración!$V$9),tblResultCalib[[#This Row],[Promedio Patrón]]*Calibración!$W$9/100+Calibración!$X$9,0)),"") -> 0 | V21: =IFERROR(ABS(IF(OR(CertTempC<Calibración!$U$10,CertTempC>Calibración!$V$10),tblResultCalib[[#This Row],[Promedio Patrón]]*Calibración!$W$10/100+Calibración!$X$10,0)),"") -> 0
B22: 8 | C22: ='NI-R01-MCIT-T-01'!B31 -> 0 | D22: ='NI-R01-MCIT-T-01'!C31 -> 0 | E22: ='NI-R01-MCIT-T-01'!D31 -> 0 | F22: ='NI-R01-MCIT-T-01'!E31 -> 0 | G22: ='NI-R01-MCIT-T-01'!F31 -> 0 | H22: ='NI-R01-MCIT-T-01'!G31 -> 0 | I22: =IFERROR(AVERAGE(C22,E22,G22),"") -> 0 | J22: =IFERROR(AVERAGE(D22,F22,H22),"") -> 0 | K22: =IFERROR(IF(C22="","",_xlfn.STDEV.S(D22,F22,H22)),"") -> 0 | M22: 8 | N22: =IFERROR(AVERAGE(C22,E22,G22),"") -> 0 | O22: =IF(tblResultCalib[[#This Row],[Promedio Patrón]]="","",IFERROR(IF(coef_unidad=32,(OFFSET($V$36,0,tblResultCalib[[#This Row],['#]]-1)),OFFSET($V$36,0,tblResultCalib[[#This Row],['#]]-1)+coef_unidad),TREND($O$31:OFFSET($O$31,NumPuntosCalib-1,0),$N$31:OFFSET($N$31,NumPuntosCalib-1,0),tblResultCalib[[#This Row],[Promedio Patrón]]))) -> -0.0020157983 | P22: =IFERROR(tblResultCalib[[#This Row],[Promedio Patrón]]+tblResultCalib[[#This Row],[Corrección patrón]],"") -> -0.0020157983 | Q22: =IFERROR(J22,"") -> 0 | R22: =IFERROR(tblResultCalib[[#This Row],[Patrón corregido]]-tblResultCalib[[#This Row],[Promedio equipo]],"") -> -0.0020157983 | S22: =IF(tblResultCalib[[#This Row],[Promedio Patrón]]="","",IFERROR(IF(coef_unidad=32,(OFFSET($V$47,0,tblResultCalib[[#This Row],['#]]-1)),OFFSET($V$47,0,tblResultCalib[[#This Row],['#]]-1)+coef_unidad),TREND($P$31:OFFSET($P$31,NumPuntosCalib-1,0),$N$31:OFFSET($N$31,NumPuntosCalib-1,0),tblResultCalib[[#This Row],[Promedio Patrón]]))) -> 0.02 | T22: =IF(tblResultCalib[[#This Row],[Promedio Patrón]]="","",IFERROR(IF(coef_unidad=32,(OFFSET($V$58,0,tblResultCalib[[#This Row],['#]]-1)),OFFSET($V$58,0,tblResultCalib[[#This Row],['#]]-1)+coef_unidad),TREND($Q$31:OFFSET($Q$31,NumPuntosCalib-1,0),$N$31:OFFSET($N$31,NumPuntosCalib-1,0),tblResultCalib[[#This Row],[Promedio Patrón]]))) -> 0.001013644 | U22: =IFERROR(ABS(IF(OR(CertTempC<Calibración!$U$9,CertTempC>Calibración!$V$9),tblResultCalib[[#This Row],[Promedio Patrón]]*Calibración!$W$9/100+Calibración!$X$9,0)),"") -> 0 | V22: =IFERROR(ABS(IF(OR(CertTempC<Calibración!$U$10,CertTempC>Calibración!$V$10),tblResultCalib[[#This Row],[Promedio Patrón]]*Calibración!$W$10/100+Calibración!$X$10,0)),"") -> 0
B23: 9 | C23: ='NI-R01-MCIT-T-01'!B32 -> 0 | D23: ='NI-R01-MCIT-T-01'!C32 -> 0 | E23: ='NI-R01-MCIT-T-01'!D32 -> 0 | F23: ='NI-R01-MCIT-T-01'!E32 -> 0 | G23: ='NI-R01-MCIT-T-01'!F32 -> 0 | H23: ='NI-R01-MCIT-T-01'!G32 -> 0 | I23: =IFERROR(AVERAGE(C23,E23,G23),"") -> 0 | J23: =IFERROR(AVERAGE(D23,F23,H23),"") -> 0 | K23: =IFERROR(IF(C23="","",_xlfn.STDEV.S(D23,F23,H23)),"") -> 0 | M23: 9 | N23: =IFERROR(AVERAGE(C23,E23,G23),"") -> 0 | O23: =IF(tblResultCalib[[#This Row],[Promedio Patrón]]="","",IFERROR(IF(coef_unidad=32,(OFFSET($V$36,0,tblResultCalib[[#This Row],['#]]-1)),OFFSET($V$36,0,tblResultCalib[[#This Row],['#]]-1)+coef_unidad),TREND($O$31:OFFSET($O$31,NumPuntosCalib-1,0),$N$31:OFFSET($N$31,NumPuntosCalib-1,0),tblResultCalib[[#This Row],[Promedio Patrón]]))) -> -0.0020157983 | P23: =IFERROR(tblResultCalib[[#This Row],[Promedio Patrón]]+tblResultCalib[[#This Row],[Corrección patrón]],"") -> -0.0020157983 | Q23: =IFERROR(J23,"") -> 0 | R23: =IFERROR(tblResultCalib[[#This Row],[Patrón corregido]]-tblResultCalib[[#This Row],[Promedio equipo]],"") -> -0.0020157983 | S23: =IF(tblResultCalib[[#This Row],[Promedio Patrón]]="","",IFERROR(IF(coef_unidad=32,(OFFSET($V$47,0,tblResultCalib[[#This Row],['#]]-1)),OFFSET($V$47,0,tblResultCalib[[#This Row],['#]]-1)+coef_unidad),TREND($P$31:OFFSET($P$31,NumPuntosCalib-1,0),$N$31:OFFSET($N$31,NumPuntosCalib-1,0),tblResultCalib[[#This Row],[Promedio Patrón]]))) -> 0.02 | T23: =IF(tblResultCalib[[#This Row],[Promedio Patrón]]="","",IFERROR(IF(coef_unidad=32,(OFFSET($V$58,0,tblResultCalib[[#This Row],['#]]-1)),OFFSET($V$58,0,tblResultCalib[[#This Row],['#]]-1)+coef_unidad),TREND($Q$31:OFFSET($Q$31,NumPuntosCalib-1,0),$N$31:OFFSET($N$31,NumPuntosCalib-1,0),tblResultCalib[[#This Row],[Promedio Patrón]]))) -> 0.001013644 | U23: =IFERROR(ABS(IF(OR(CertTempC<Calibración!$U$9,CertTempC>Calibración!$V$9),tblResultCalib[[#This Row],[Promedio Patrón]]*Calibración!$W$9/100+Calibración!$X$9,0)),"") -> 0 | V23: =IFERROR(ABS(IF(OR(CertTempC<Calibración!$U$10,CertTempC>Calibración!$V$10),tblResultCalib[[#This Row],[Promedio Patrón]]*Calibración!$W$10/100+Calibración!$X$10,0)),"") -> 0
B24: 10 | C24: ='NI-R01-MCIT-T-01'!B33 -> 0 | D24: ='NI-R01-MCIT-T-01'!C33 -> 0 | E24: ='NI-R01-MCIT-T-01'!D33 -> 0 | F24: ='NI-R01-MCIT-T-01'!E33 -> 0 | G24: ='NI-R01-MCIT-T-01'!F33 -> 0 | H24: ='NI-R01-MCIT-T-01'!G33 -> 0 | I24: =IFERROR(AVERAGE(C24,E24,G24),"") -> 0 | J24: =IFERROR(AVERAGE(D24,F24,H24),"") -> 0 | K24: =IFERROR(IF(C24="","",_xlfn.STDEV.S(D24,F24,H24)),"") -> 0 | M24: 10 | N24: =IFERROR(AVERAGE(C24,E24,G24),"") -> 0 | O24: =IF(tblResultCalib[[#This Row],[Promedio Patrón]]="","",IFERROR(IF(coef_unidad=32,(OFFSET($V$36,0,tblResultCalib[[#This Row],['#]]-1)),OFFSET($V$36,0,tblResultCalib[[#This Row],['#]]-1)+coef_unidad),TREND($O$31:OFFSET($O$31,NumPuntosCalib-1,0),$N$31:OFFSET($N$31,NumPuntosCalib-1,0),tblResultCalib[[#This Row],[Promedio Patrón]]))) -> -0.0020157983 | P24: =IFERROR(tblResultCalib[[#This Row],[Promedio Patrón]]+tblResultCalib[[#This Row],[Corrección patrón]],"") -> -0.0020157983 | Q24: =IFERROR(J24,"") -> 0 | R24: =IFERROR(tblResultCalib[[#This Row],[Patrón corregido]]-tblResultCalib[[#This Row],[Promedio equipo]],"") -> -0.0020157983 | S24: =IF(tblResultCalib[[#This Row],[Promedio Patrón]]="","",IFERROR(IF(coef_unidad=32,(OFFSET($V$47,0,tblResultCalib[[#This Row],['#]]-1)),OFFSET($V$47,0,tblResultCalib[[#This Row],['#]]-1)+coef_unidad),TREND($P$31:OFFSET($P$31,NumPuntosCalib-1,0),$N$31:OFFSET($N$31,NumPuntosCalib-1,0),tblResultCalib[[#This Row],[Promedio Patrón]]))) -> 0.02 | T24: =IF(tblResultCalib[[#This Row],[Promedio Patrón]]="","",IFERROR(IF(coef_unidad=32,(OFFSET($V$58,0,tblResultCalib[[#This Row],['#]]-1)),OFFSET($V$58,0,tblResultCalib[[#This Row],['#]]-1)+coef_unidad),TREND($Q$31:OFFSET($Q$31,NumPuntosCalib-1,0),$N$31:OFFSET($N$31,NumPuntosCalib-1,0),tblResultCalib[[#This Row],[Promedio Patrón]]))) -> 0.001013644 | U24: =IFERROR(ABS(IF(OR(CertTempC<Calibración!$U$9,CertTempC>Calibración!$V$9),tblResultCalib[[#This Row],[Promedio Patrón]]*Calibración!$W$9/100+Calibración!$X$9,0)),"") -> 0 | V24: =IFERROR(ABS(IF(OR(CertTempC<Calibración!$U$10,CertTempC>Calibración!$V$10),tblResultCalib[[#This Row],[Promedio Patrón]]*Calibración!$W$10/100+Calibración!$X$10,0)),"") -> 0
M27: Interpolación corrección y deriva patrón | Q27: =CONCATENATE("[Todo en ", unidad,"]") -> [Todo en °C]
U28: Interpolación corrección patrón | Y28: =CONCATENATE("[Todo en ", unidad,"]") -> [Todo en °C]
C29: Tabla de resultados de la calibración | N29: Patrón | O29: =J5 -> NI-MCPT-05
C30: Temperatura de referencia | D30: Indicación del termómetro | E30: Corrección | F30: Incertidumbre expandida k=2 | G30: Temperatura de referencia | H30: Indicación del termómetro | I30: Corrección | J30: Incertidumbre expandida k=2 | K30: CMC | M30: # | N30: Temperatura de calibración | O30: Correccion Certificado | P30: Incertidumbre certificado U95 | Q30: Deriva patrón | U30: Punto | V30: 1 | W30: 2 | X30: 3 | Y30: 4 | Z30: 5 | AA30: 6 | AB30: 7 | AC30: 8 | AD30: 9 | AE30: 10
C31: =unidad -> °C | D31: =unidad -> °C | E31: =unidad -> °C | F31: =unidad -> °C | G31: K | H31: K | I31: K | J31: K | K31: =unidad -> °C | M31: 1 | N31: =IF(coef_unidad=32,(INDEX(Cert_patrones[[Código Patrón]:[Deriva]],MATCH($O$29,Cert_patrones[Código Patrón],0),3)*1.8+coef_unidad),INDEX(Cert_patrones[[Código Patrón]:[Deriva]],MATCH($O$29,Cert_patrones[Código Patrón],0),3)-coef_unidad) -> -30.067 | O31: =IF(coef_unidad=32,(INDEX(Cert_patrones[[Código Patrón]:[Deriva]],MATCH($O$29,Cert_patrones[Código Patrón],0),4)),INDEX(Cert_patrones[[Código Patrón]:[Deriva]],MATCH($O$29,Cert_patrones[Código Patrón],0),4)+coef_unidad) -> -0.017 | P31: =IF(coef_unidad=32,(INDEX(Cert_patrones[[Código Patrón]:[Deriva]],MATCH($O$29,Cert_patrones[Código Patrón],0),5)),INDEX(Cert_patrones[[Código Patrón]:[Deriva]],MATCH($O$29,Cert_patrones[Código Patrón],0),5)+coef_unidad) -> 0.023 | Q31: =IFERROR(IF(coef_unidad=32,(INDEX(Cert_patrones[[Código Patrón]:[Deriva]],MATCH($O$29,Cert_patrones[Código Patrón],0),9)),INDEX(Cert_patrones[[Código Patrón]:[Deriva]],MATCH($O$29,Cert_patrones[Código Patrón],0),9)+coef_unidad),0) -> 0.004 | U31: x | V31: {=TRANSPOSE(N15:N24)} -> 0 | W31: 0 | X31: 0 | Y31: 0 | Z31: 0 | AA31: 0 | AB31: 0 | AC31: 0 | AD31: 0 | AE31: 0
C32: =P15 -> -0.0020157983 | D32: =Q15 -> 0 | E32: =R15 -> -0.0020157983 | F32: =IFERROR(IF(C32<>"",'kU(E)'!$G$17*'kU(E)'!G50,""),"") -> 0.11960105 | G32: =IFERROR(N15+273.15,"") -> 273.15 | H32: =IFERROR(Q15+273.15,"") -> 273.15 | I32: =IFERROR(R15+273.15,"") -> 273.14798 | J32: =IFERROR(IF(G32<>"",('kU(E)'!$G$17+273.15)*'kU(E)'!G50,""),"") -> 546.4196 | K32: =IFERROR(IF(C32="","",IF(unidad="°C",CMC!M16,IF(unidad="K",CMC!M16+273.15,CMC!M16*9/5))),"") -> 0.071 | M32: 2 | N32: =IF(coef_unidad=32,(INDEX(Cert_patrones[[Código Patrón]:[Deriva]],MATCH($O$29,Cert_patrones[Código Patrón],0)+$M31,3)*1.8+coef_unidad),INDEX(Cert_patrones[[Código Patrón]:[Deriva]],MATCH($O$29,Cert_patrones[Código Patrón],0)+$M31,3)+coef_unidad) -> -0.018 | O32: =IF(coef_unidad=32,(INDEX(Cert_patrones[[Código Patrón]:[Deriva]],MATCH($O$29,Cert_patrones[Código Patrón],0)+$M31,4)),INDEX(Cert_patrones[[Código Patrón]:[Deriva]],MATCH($O$29,Cert_patrones[Código Patrón],0)+$M31,4)+coef_unidad) -> -0.002 | P32: =IF(coef_unidad=32,(INDEX(Cert_patrones[[Código Patrón]:[Deriva]],MATCH($O$29,Cert_patrones[Código Patrón],0)+$M31,5)),INDEX(Cert_patrones[[Código Patrón]:[Deriva]],MATCH($O$29,Cert_patrones[Código Patrón],0)+$M31,5)+coef_unidad) -> 0.02 | Q32: =IFERROR(IF(coef_unidad=32,(INDEX(Cert_patrones[[Código Patrón]:[Deriva]],MATCH($O$29,Cert_patrones[Código Patrón],0)+$M31,9)),INDEX(Cert_patrones[[Código Patrón]:[Deriva]],MATCH($O$29,Cert_patrones[Código Patrón],0)+$M31,9)+coef_unidad),0) -> 0.001 | U32: x1 | V32: =IFERROR(INDEX($N$31:$N$39,MATCH(V$31,$N$31:OFFSET($N$31,NumPuntosCalib-1,0),1)),"") -> -0.018 | W32: =IFERROR(INDEX($N$31:$N$39,MATCH(W$31,$N$31:OFFSET($N$31,NumPuntosCalib-1,0),1)),"") -> -0.018 | X32: =IFERROR(INDEX($N$31:$N$39,MATCH(X$31,$N$31:OFFSET($N$31,NumPuntosCalib-1,0),1)),"") -> -0.018 | Y32: =IFERROR(INDEX($N$31:$N$39,MATCH(Y$31,$N$31:OFFSET($N$31,NumPuntosCalib-1,0),1)),"") -> -0.018 | Z32: =IFERROR(INDEX($N$31:$N$39,MATCH(Z$31,$N$31:OFFSET($N$31,NumPuntosCalib-1,0),1)),"") -> -0.018 | AA32: =IFERROR(INDEX($N$31:$N$39,MATCH(AA$31,$N$31:OFFSET($N$31,NumPuntosCalib-1,0),1)),"") -> -0.018 | AB32: =IFERROR(INDEX($N$31:$N$39,MATCH(AB$31,$N$31:OFFSET($N$31,NumPuntosCalib-1,0),1)),"") -> -0.018 | AC32: =IFERROR(INDEX($N$31:$N$39,MATCH(AC$31,$N$31:OFFSET($N$31,NumPuntosCalib-1,0),1)),"") -> -0.018 | ... AE32: =IFERROR(INDEX($N$31:$N$39,MATCH(AE$31,$N$31:OFFSET($N$31,NumPuntosCalib-1,0),1)),"") -> -0.018
C33: =P16 -> -0.0020157983 | D33: =Q16 -> 0 | E33: =R16 -> -0.0020157983 | F33: =IFERROR(IF(C33<>"",'kU(E)'!$H$17*'kU(E)'!G51,""),"") -> 0.11960105 | G33: =IFERROR(N16+273.15,"") -> 273.15 | H33: =IFERROR(Q16+273.15,"") -> 273.15 | I33: =IFERROR(R16+273.15,"") -> 273.14798 | J33: =IFERROR(IF(G33<>"",('kU(E)'!$H$17+273.15)*'kU(E)'!G51,""),"") -> 546.4196 | K33: =IFERROR(IF(C33="","",IF(unidad="°C",CMC!M17,IF(unidad="K",CMC!M17+273.15,CMC!M17*9/5))),"") -> 0.071 | M33: 3 | N33: =IF(coef_unidad=32,(INDEX(Cert_patrones[[Código Patrón]:[Deriva]],MATCH($O$29,Cert_patrones[Código Patrón],0)+$M32,3)*1.8+coef_unidad),INDEX(Cert_patrones[[Código Patrón]:[Deriva]],MATCH($O$29,Cert_patrones[Código Patrón],0)+$M32,3)+coef_unidad) -> 25.048 | O33: =IF(coef_unidad=32,(INDEX(Cert_patrones[[Código Patrón]:[Deriva]],MATCH($O$29,Cert_patrones[Código Patrón],0)+$M32,4)),INDEX(Cert_patrones[[Código Patrón]:[Deriva]],MATCH($O$29,Cert_patrones[Código Patrón],0)+$M32,4)+coef_unidad) -> -0.024 | P33: =IF(coef_unidad=32,(INDEX(Cert_patrones[[Código Patrón]:[Deriva]],MATCH($O$29,Cert_patrones[Código Patrón],0)+$M32,5)),INDEX(Cert_patrones[[Código Patrón]:[Deriva]],MATCH($O$29,Cert_patrones[Código Patrón],0)+$M32,5)+coef_unidad) -> 0.02 | Q33: =IFERROR(IF(coef_unidad=32,(INDEX(Cert_patrones[[Código Patrón]:[Deriva]],MATCH($O$29,Cert_patrones[Código Patrón],0)+$M32,9)),INDEX(Cert_patrones[[Código Patrón]:[Deriva]],MATCH($O$29,Cert_patrones[Código Patrón],0)+$M32,9)+coef_unidad),0) -> 0.02 | U33: y1 | V33: =IFERROR(INDEX($O$31:$O$39,MATCH(V$31,$N$31:OFFSET($N$31,NumPuntosCalib-1,0),1)),"") -> -0.002 | W33: =IFERROR(INDEX($O$31:$O$39,MATCH(W$31,$N$31:OFFSET($N$31,NumPuntosCalib-1,0),1)),"") -> -0.002 | X33: =IFERROR(INDEX($O$31:$O$39,MATCH(X$31,$N$31:OFFSET($N$31,NumPuntosCalib-1,0),1)),"") -> -0.002 | Y33: =IFERROR(INDEX($O$31:$O$39,MATCH(Y$31,$N$31:OFFSET($N$31,NumPuntosCalib-1,0),1)),"") -> -0.002 | Z33: =IFERROR(INDEX($O$31:$O$39,MATCH(Z$31,$N$31:OFFSET($N$31,NumPuntosCalib-1,0),1)),"") -> -0.002 | AA33: =IFERROR(INDEX($O$31:$O$39,MATCH(AA$31,$N$31:OFFSET($N$31,NumPuntosCalib-1,0),1)),"") -> -0.002 | AB33: =IFERROR(INDEX($O$31:$O$39,MATCH(AB$31,$N$31:OFFSET($N$31,NumPuntosCalib-1,0),1)),"") -> -0.002 | AC33: =IFERROR(INDEX($O$31:$O$39,MATCH(AC$31,$N$31:OFFSET($N$31,NumPuntosCalib-1,0),1)),"") -> -0.002 | ... AE33: =IFERROR(INDEX($O$31:$O$39,MATCH(AE$31,$N$31:OFFSET($N$31,NumPuntosCalib-1,0),1)),"") -> -0.002
